<?xml version="1.0" ?>
<robot name="autolabor_description">
  <joint name="dummy_joint" type="fixed">
    <parent link="odom"/>
    <child link="base_link"/>
    <origin xyz="0 0 0" rpy="0 0 0"/>
  </joint>
  <joint name="cam_joint" type="fixed">
    <parent link="base_link"/>
    <child link="camera"/>
    <origin xyz="0 0.8 1" rpy="0 1.5707 0"/>
  </joint>
  <joint name="frjoint" type="revolute">
    <parent link="base_link"/>
    <child link="front_right_wheel"/>
    <origin rpy="0  0  0" xyz="-0.2786993682384491 -0.12106603384017944 -0.02870245650410652"/>
    <axis xyz="1  0  0"/>
    <limit effort="10" lower="-1.79769e+308" upper="1.79769e+308" velocity="10"/>
  </joint>
  <joint name="brjoint" type="fixed">
    <parent link="base_link"/>
    <child link="back_right_wheel"/>
    <origin rpy="0  0  0" xyz="-0.2786993682384491 0.2670927047729492 -0.03011767752468586"/>
  </joint>
  <joint name="fljoint" type="revolute">
    <parent link="base_link"/>
    <child link="front_left_wheel"/>
    <origin rpy="0  0  0" xyz="0.2827356159687042 -0.1203216165304184 -0.02870248258113861"/>
    <axis xyz="1  0  0"/>
    <limit effort="10" lower="-1.79769e+308" upper="1.79769e+308" velocity="10"/>
  </joint>
  <joint name="bljoint" type="fixed">
    <parent link="base_link"/>
    <child link="back_left_wheel"/>
    <origin rpy="0  0  0" xyz="0.2827356159687042 0.2670927047729492 -0.03086165525019169"/>
  </joint>
  <link name="odom"/>
  <link name="base_link">
    <inertial>
      <mass value="10"/>
      <origin rpy="0  0  0" xyz="0  0  0"/>
      <inertia ixx="0.166667" ixy="0" ixz="0" iyy="0.166667" iyz="0" izz="0.166667"/>
    </inertial>
    <collision name="collision">
      <origin rpy="0  0  0" xyz="0  0  0"/>
      <geometry>
        <mesh filename="package://autolabor_description/meshes/body.stl" scale="1 1 1"/>
      </geometry>
    </collision>
    <visual name="visual">
      <origin rpy="0  0  0" xyz="0  0  0"/>
      <geometry>
        <mesh filename="package://autolabor_description/meshes/body.stl" scale="1 1 1"/>
      </geometry>
    </visual>
  </link>
  <link name="camera">
    <inertial>
      <mass value="0.001"/>
      <origin rpy="0 0 0" xyz="0 0 0"/>
      <inertia ixx="0.000166667" iyy="0.000166667" izz="0.000166667" ixy="0" ixz="0" iyz="0"/>
    </inertial>
    <collision>
      <origin rpy="0 0 0" xyz="0 0 0"/>
      <geometry>
        <box size="0.1 0.1 0.1"/>
      </geometry>
    </collision>
    <visual>
      <origin rpy="0 0 0" xyz="0 0 0"/>
      <geometry>
        <box size="0.1 0.1 0.1"/>
      </geometry>
    </visual>
  </link>
  <link name="front_right_wheel">
    <inertial>
      <mass value="1"/>
      <origin rpy="0  0  0" xyz="0  0  0"/>
      <inertia ixx="0.166667" ixy="0" ixz="0" iyy="0.166667" iyz="0" izz="0.166667"/>
    </inertial>
    <collision name="collision">
      <origin rpy="0  0  0" xyz="0  0  0"/>
      <geometry>
        <mesh filename="package://autolabor_description/meshes/wheel.stl" scale="1 1 1"/>
      </geometry>
    </collision>
    <visual name="visual">
      <origin rpy="0  0  0" xyz="0  0  0"/>
      <geometry>
        <mesh filename="package://autolabor_description/meshes/wheel.stl" scale="1 1 1"/>
      </geometry>
    </visual>
  </link>
  <link name="back_right_wheel">
    <inertial>
      <mass value="1"/>
      <origin rpy="0  0  0" xyz="0  0  0"/>
      <inertia ixx="0.166667" ixy="0" ixz="0" iyy="0.166667" iyz="0" izz="0.166667"/>
    </inertial>
    <collision name="collision">
      <origin rpy="0  0  0" xyz="0  0  0"/>
      <geometry>
        <mesh filename="package://autolabor_description/meshes/wheel.stl" scale="1 1 1"/>
      </geometry>
    </collision>
    <visual name="visual">
      <origin rpy="0  0  0" xyz="0  0  0"/>
      <geometry>
        <mesh filename="package://autolabor_description/meshes/wheel.stl" scale="1 1 1"/>
      </geometry>
    </visual>
  </link>
  <link name="front_left_wheel">
    <inertial>
      <mass value="1"/>
      <origin rpy="0  0  0" xyz="0  0  0"/>
      <inertia ixx="0.166667" ixy="0" ixz="0" iyy="0.166667" iyz="0" izz="0.166667"/>
    </inertial>
    <collision name="collision">
      <origin rpy="0  0  0" xyz="0  0  0"/>
      <geometry>
        <mesh filename="package://autolabor_description/meshes/wheel.stl" scale="1 1 1"/>
      </geometry>
    </collision>
    <visual name="visual">
      <origin rpy="0  0  0" xyz="0  0  0"/>
      <geometry>
        <mesh filename="package://autolabor_description/meshes/wheel.stl" scale="1 1 1"/>
      </geometry>
    </visual>
  </link>
  <link name="back_left_wheel">
    <inertial>
      <mass value="1"/>
      <origin rpy="0  0  0" xyz="0  0  0"/>
      <inertia ixx="0.166667" ixy="0" ixz="0" iyy="0.166667" iyz="0" izz="0.166667"/>
    </inertial>
    <collision name="collision">
      <origin rpy="0  0  0" xyz="0  0  0"/>
      <geometry>
        <mesh filename="package://autolabor_description/meshes/wheel.stl" scale="1 1 1"/>
      </geometry>
    </collision>
    <visual name="visual">
      <origin rpy="0  0  0" xyz="0  0  0"/>
      <geometry>
        <mesh filename="package://autolabor_description/meshes/wheel.stl" scale="1 1 1"/>
      </geometry>
    </visual>
  </link>
  <transmission name="tran1">
    <type>transmission_interface/SimpleTransmission</type>
    <joint name="frjoint">
      <hardwareInterface>hardware_interface/VelocityJointInterface</hardwareInterface>
    </joint>
    <actuator name="motor1">
      <mechanicalReduction>1</mechanicalReduction>
    </actuator>
  </transmission>
  <transmission name="tran2">
    <type>transmission_interface/SimpleTransmission</type>
    <joint name="fljoint">
      <hardwareInterface>hardware_interface/VelocityJointInterface</hardwareInterface>
    </joint>
    <actuator name="motor2">
      <mechanicalReduction>1</mechanicalReduction>
    </actuator>
  </transmission>

  <gazebo reference="camera">
    <sensor type="camera" name="camera">
      <update_rate>30.0</update_rate>
      <camera name="scaner">
        <horizontal_fov>1.5</horizontal_fov>
        <image>
          <width>320</width>
          <height>240</height>
          <format>R8G8B8</format>
        </image>
        <clip>
          <near>0.01</near>
          <far>100</far>
        </clip>
      </camera>
      <plugin name="camera_controller" filename="libgazebo_ros_camera.so">
        <alwaysOn>true</alwaysOn>
        <updateRate>0.0</updateRate>
        <cameraName>autolabor_pro1/camera1</cameraName>
        <imageTopicName>image_raw</imageTopicName>
        <cameraInfoTopicName>camera_info</cameraInfoTopicName>
        <frameName>camera_link</frameName>
      </plugin>
    </sensor>
  </gazebo>

  <gazebo>
    <plugin name="gazebo_ros_control" filename="libgazebo_ros_control.so">
      <robotNamespace>/autolabor_pro1</robotNamespace>
      <robotSimType>gazebo_ros_control/DefaultRobotHWSim</robotSimType>
    </plugin>
  </gazebo>
</robot>
