<?xml version="1.0" ?>
<robot name="autolabor_description">
  <joint name="dummy_joint" type="fixed">
    <parent link="odom"/>
    <child link="base_link"/>
    <origin xyz="0 0 0" rpy="0 0 0"/>
  </joint>
  <joint name="frjoint" type="revolute">
    <parent link="base_link"/>
    <child link="front_right_wheel"/>
    <origin rpy="0  0  0" xyz="-0.2786993682384491 -0.12106603384017944 -0.02870245650410652"/>
    <axis xyz="0  0  1"/>
    <limit effort="10" lower="-0.3" upper="0.3" velocity="10"/>
  </joint>
  <joint name="brjoint" type="revolute">
    <parent link="base_link"/>
    <child link="back_right_wheel"/>
    <origin rpy="0  0  0" xyz="-0.2786993682384491 0.2670927047729492 -0.03011767752468586"/>
    <axis xyz="1  0  0"/>
    <limit effort="10" lower="-1.79769e+308" upper="1.79769e+308" velocity="10"/>
  </joint>
  <joint name="fljoint" type="revolute">
    <parent link="base_link"/>
    <child link="front_left_wheel"/>
    <origin rpy="0  0  3.14159" xyz="0.2827356159687042 -0.1203216165304184 -0.02870248258113861"/>
    <axis xyz="0  0  1"/>
    <limit effort="10" lower="-0.3" upper="0.3" velocity="10"/>
  </joint>
  <joint name="bljoint" type="revolute">
    <parent link="base_link"/>
    <child link="back_left_wheel"/>
    <origin rpy="0  0  3.14159" xyz="0.2827356159687042 0.2670927047729492 -0.03086165525019169"/>
    <axis xyz="-1  0  0"/>
    <limit effort="10" lower="-1.79769e+308" upper="1.79769e+308" velocity="10"/>
  </joint>
  <link name="odom"/>
  <link name="base_link">
    <inertial>
      <mass value="10"/>
      <origin rpy="0  0  0" xyz="0  0  0"/>
      <inertia ixx="0.166667" ixy="0" ixz="0" iyy="0.166667" iyz="0" izz="0.166667"/>
    </inertial>
    <collision name="collision">
      <origin rpy="0  0  0" xyz="0  0  0"/>
      <geometry>
        <mesh filename="package://autolabor_description/meshes/body.stl" scale="1 1 1"/>
      </geometry>
    </collision>
    <visual name="visual">
      <origin rpy="0  0  0" xyz="0  0  0"/>
      <geometry>
        <mesh filename="package://autolabor_description/meshes/body.stl" scale="1 1 1"/>
      </geometry>
    </visual>
  </link>
  <link name="front_right_wheel">
    <inertial>
      <mass value="1"/>
      <origin rpy="0  0  0" xyz="0  0  0"/>
      <inertia ixx="0.166667" ixy="0" ixz="0" iyy="0.166667" iyz="0" izz="0.166667"/>
    </inertial>
    <collision name="collision">
      <origin rpy="0  0  0" xyz="0  0  0"/>
      <geometry>
        <mesh filename="package://autolabor_description/meshes/wheel.stl" scale="1 1 1"/>
      </geometry>
    </collision>
    <visual name="visual">
      <origin rpy="0  0  0" xyz="0  0  0"/>
      <geometry>
        <mesh filename="package://autolabor_description/meshes/wheel.stl" scale="1 1 1"/>
      </geometry>
    </visual>
  </link>
  <link name="back_right_wheel">
    <inertial>
      <mass value="1"/>
      <origin rpy="0  0  0" xyz="0  0  0"/>
      <inertia ixx="0.166667" ixy="0" ixz="0" iyy="0.166667" iyz="0" izz="0.166667"/>
    </inertial>
    <collision name="collision">
      <origin rpy="0  0  0" xyz="0  0  0"/>
      <geometry>
        <mesh filename="package://autolabor_description/meshes/wheel.stl" scale="1 1 1"/>
      </geometry>
    </collision>
    <visual name="visual">
      <origin rpy="0  0  0" xyz="0  0  0"/>
      <geometry>
        <mesh filename="package://autolabor_description/meshes/wheel.stl" scale="1 1 1"/>
      </geometry>
    </visual>
  </link>
  <link name="front_left_wheel">
    <inertial>
      <mass value="1"/>
      <origin rpy="0  0  0" xyz="0  0  0"/>
      <inertia ixx="0.166667" ixy="0" ixz="0" iyy="0.166667" iyz="0" izz="0.166667"/>
    </inertial>
    <collision name="collision">
      <origin rpy="0  0  0" xyz="0  0  0"/>
      <geometry>
        <mesh filename="package://autolabor_description/meshes/wheel.stl" scale="1 1 1"/>
      </geometry>
    </collision>
    <visual name="visual">
      <origin rpy="0  0  0" xyz="0  0  0"/>
      <geometry>
        <mesh filename="package://autolabor_description/meshes/wheel.stl" scale="1 1 1"/>
      </geometry>
    </visual>
  </link>
  <link name="back_left_wheel">
    <inertial>
      <mass value="1"/>
      <origin rpy="0  0  0" xyz="0  0  0"/>
      <inertia ixx="0.166667" ixy="0" ixz="0" iyy="0.166667" iyz="0" izz="0.166667"/>
    </inertial>
    <collision name="collision">
      <origin rpy="0  0  0" xyz="0  0  0"/>
      <geometry>
        <mesh filename="package://autolabor_description/meshes/wheel.stl" scale="1 1 1"/>
      </geometry>
    </collision>
    <visual name="visual">
      <origin rpy="0  0  0" xyz="0  0  0"/>
      <geometry>
        <mesh filename="package://autolabor_description/meshes/wheel.stl" scale="1 1 1"/>
      </geometry>
    </visual>
  </link>
  <transmission name="tran1">
    <type>transmission_interface/SimpleTransmission</type>
    <joint name="frjoint">
      <hardwareInterface>hardware_interface/PositionJointInterface</hardwareInterface>
    </joint>
    <actuator name="motor1">
      <mechanicalReduction>1</mechanicalReduction>
    </actuator>
  </transmission>
  <transmission name="tran2">
    <type>transmission_interface/SimpleTransmission</type>
    <joint name="fljoint">
      <hardwareInterface>hardware_interface/PositionJointInterface</hardwareInterface>
    </joint>
    <actuator name="motor2">
      <mechanicalReduction>1</mechanicalReduction>
    </actuator>
  </transmission>
  <transmission name="tran3">
    <type>transmission_interface/SimpleTransmission</type>
    <joint name="brjoint">
      <hardwareInterface>hardware_interface/VelocityJointInterface</hardwareInterface>
    </joint>
    <actuator name="motor3">
      <mechanicalReduction>1</mechanicalReduction>
    </actuator>
  </transmission>
  <transmission name="tran4">
    <type>transmission_interface/SimpleTransmission</type>
    <joint name="bljoint">
      <hardwareInterface>hardware_interface/VelocityJointInterface</hardwareInterface>
    </joint>
    <actuator name="motor4">
      <mechanicalReduction>1</mechanicalReduction>
    </actuator>
  </transmission>

  <gazebo reference="base_link">
    <mu1>0.2</mu1>
    <mu2>0.2</mu2>
  </gazebo>
  <gazebo reference="front_right_wheel">
    <mu1>0.2</mu1>
    <mu2>0.2</mu2>
  </gazebo>
  <gazebo reference="back_right_wheel">
    <mu1>0.2</mu1>
    <mu2>0.2</mu2>
  </gazebo>
  <gazebo reference="front_left_wheel">
    <mu1>0.2</mu1>
    <mu2>0.2</mu2>
  </gazebo>
  <gazebo reference="back_left_wheel">
    <mu1>0.2</mu1>
    <mu2>0.2</mu2>
  </gazebo>

  <gazebo>
    <self_collide>true</self_collide>
    <plugin name="gazebo_ros_control" filename="libgazebo_ros_control.so">
    <robotNamespace>/autolabor_pro1</robotNamespace>
    <robotSimType>gazebo_ros_control/DefaultRobotHWSim</robotSimType>
  </plugin>
  </gazebo>
</robot>
