<robot name="autolabor_description">
  <link name="world" />
  <link name="base_link">
    <visual>
      <origin
        xyz="0 0 0"
        rpy="0 0 0" />
      <geometry>
        <mesh
          filename="package://autolabor_description/meshes/body.stl" />
      </geometry>
      <material
        name="">
        <color
          rgba="0.96 0.81 0.36 1" />
      </material>
    </visual>
    <collision>
     <origin
        xyz="0 0 0"
        rpy="0 0 0" />
      <geometry>
        <mesh
          filename="package://autolabor_description/meshes/body.stl" />
      </geometry>
    </collision>
    <inertial>
      <mass value="10"/>
      <origin xyz="0 0 0" rpy="0 0 0"/>
      <inertia ixx="0.000633" ixy="0.000002" ixz="0.000006" iyy="0.000523" iyz="0" izz="0.000999" />
    </inertial>
  </link>
  <link name="front_right_link">
    <visual>
      <origin
        xyz="0 0 0"
        rpy="0 0 0" />
      <geometry>
        <mesh
          filename="package://autolabor_description/meshes/wheel.stl" />
      </geometry>
      <material
        name="">
        <color
          rgba="0.96 0.81 0.36 1" />
      </material>
    </visual>
    <collision>
     <origin
        xyz="0 0 0"
        rpy="0 0 0" />
      <geometry>
        <mesh
          filename="package://autolabor_description/meshes/wheel.stl" />
      </geometry>
    </collision>
    <inertial>
      <mass value="1"/>
      <origin xyz="0 0 0" rpy="0 0 0"/>
      <inertia ixx="0.000026" ixy="0" ixz="0" iyy="0.000227" iyz="0" izz="0.000227" />
    </inertial>
  </link>
  <link name="front_left_link">
    <visual>
      <origin
        xyz="0 0 0"
        rpy="0 0 0" />
      <geometry>
        <mesh
          filename="package://autolabor_description/meshes/wheel.stl" />
      </geometry>
      <material
        name="">
        <color
          rgba="0.96 0.81 0.36 1" />
      </material>
    </visual>
    <collision>
     <origin
        xyz="0 0 0"
        rpy="0 0 0" />
      <geometry>
        <mesh
          filename="package://autolabor_description/meshes/wheel.stl" />
      </geometry>
    </collision>
    <inertial>
      <mass value="1"/>
      <origin xyz="0 0 0" rpy="0 0 0"/>
      <inertia ixx="0.000026" ixy="0" ixz="0" iyy="0.000227" iyz="0" izz="0.000227" />
    </inertial>
  </link>
  <link name="back_right_link">
    <visual>
      <origin
        xyz="0 0 0"
        rpy="0 0 0" />
      <geometry>
        <mesh
          filename="package://autolabor_description/meshes/wheel.stl" />
      </geometry>
      <material
        name="">
        <color
          rgba="0.96 0.81 0.36 1" />
      </material>
    </visual>
    <collision>
     <origin
        xyz="0 0 0"
        rpy="0 0 0" />
      <geometry>
        <mesh
          filename="package://autolabor_description/meshes/wheel.stl" />
      </geometry>
    </collision>
    <inertial>
      <mass value="1"/>
      <origin xyz="0 0 0" rpy="0 0 0"/>
      <inertia ixx="0.000026" ixy="0" ixz="0" iyy="0.000227" iyz="0" izz="0.000227" />
    </inertial>
  </link>
  <link name="back_left_link">
    <visual>
      <origin
        xyz="0 0 0"
        rpy="0 0 0" />
      <geometry>
        <mesh
          filename="package://autolabor_description/meshes/wheel.stl" />
      </geometry>
      <material
        name="">
        <color
          rgba="0.96 0.81 0.36 1" />
      </material>
    </visual>
    <collision>
     <origin
        xyz="0 0 0"
        rpy="0 0 0" />
      <geometry>
        <mesh
          filename="package://autolabor_description/meshes/wheel.stl" />
      </geometry>
    </collision>
    <inertial>
      <mass value="1"/>
      <origin xyz="0 0 0" rpy="0 0 0"/>
      <inertia ixx="0.000026" ixy="0" ixz="0" iyy="0.000227" iyz="0" izz="0.000227" />
    </inertial>
  </link>


  <joint name="fixed_joint" type="fixed">
    <origin xyz="0 0 0" rpy="0 0 0" />
    <parent link="world" />
    <child link="base_link" />
  </joint>
  <joint name="frjoint" type="revolute">
    <origin xyz="-0.27769 -0.1894 0.02618" rpy="0 0 0" />
    <axis xyz="1 0 0" />
    <limit upper="0" lower="-1.57" velocity="10" effort="1" />
    <parent link="base_link" />
    <child link="front_right_link" />
  </joint>
  <joint name="fljoint" type="revolute">
    <origin xyz="0.27769 -0.1894 0.02618" rpy="0 0 3.14159" />
    <axis xyz="1 0 0" />
    <limit upper="0" lower="-1.57" velocity="10" effort="1" />
    <parent link="base_link" />
    <child link="front_left_link" />
  </joint>
  <joint name="brjoint" type="revolute">
    <origin xyz="-0.27769 0.19609 0.02618" rpy="0 0 0" />
    <axis xyz="1 0 0" />
    <limit upper="0" lower="-1.57" velocity="10" effort="1" />
    <parent link="base_link" />
    <child link="back_right_link" />
  </joint>
  <joint name="bljoint" type="revolute">
    <origin xyz="0.27769 0.19609 0.02618" rpy="0 0 3.14159" />
    <axis xyz="1 0 0" />
    <limit upper="0" lower="-1.57" velocity="10" effort="1" />
    <parent link="base_link" />
    <child link="back_left_link" />
  </joint>


  <transmission name="tran1">
    <type>transmission_interface/SimpleTransmission</type>
    <joint name="frjoint">
      <hardwareInterface>hardware_interface/VelocityJointInterface</hardwareInterface>
    </joint>
    <actuator name="motor1">
      <mechanicalReduction>1</mechanicalReduction>
    </actuator>
  </transmission>
  <transmission name="tran2">
    <type>transmission_interface/SimpleTransmission</type>
    <joint name="fljoint">
      <hardwareInterface>hardware_interface/VelocityJointInterface</hardwareInterface>
    </joint>
    <actuator name="motor2">
      <mechanicalReduction>1</mechanicalReduction>
    </actuator>
  </transmission>
  <transmission name="tran3">
    <type>transmission_interface/SimpleTransmission</type>
    <joint name="brjoint">
      <hardwareInterface>hardware_interface/VelocityJointInterface</hardwareInterface>
    </joint>
    <actuator name="motor1">
      <mechanicalReduction>1</mechanicalReduction>
    </actuator>
  </transmission>
  <transmission name="tran4">
    <type>transmission_interface/SimpleTransmission</type>
    <joint name="bljoint">
      <hardwareInterface>hardware_interface/VelocityJointInterface</hardwareInterface>
    </joint>
    <actuator name="motor2">
      <mechanicalReduction>1</mechanicalReduction>
    </actuator>
  </transmission>
  <gazebo>
    <plugin name="gazebo_ros_control" filename="libgazebo_ros_control.so">
    <robotNamespace>/autolabor_pro1</robotNamespace>
    <robotSimType>gazebo_ros_control/DefaultRobotHWSim</robotSimType>
  </plugin>
  </gazebo>
</robot>
